Workbook

Sheet Cover Page
B2: PCI DSS v4.0 COMPLIANCE CHECKLIST
B5: Nile Crest Bank (NCB) · Cairo, Egypt
B7: Organization: | C7: New Nile Bank
B8: Assessment Type: | C8: Self-Assessment (SAQ)
B9: PCI DSS Version: | C9: v4.0 (Published March 2022)
B10: Scope: | C10: ATM Network (Base24), Card Issuance, Payment Switch
B11: Assessor / Owner: | C11: Mohamed Ragab – Head of IT Security
B12: Review Approved by: | C12: Samara– CISO
B13: Date Prepared: | C13: 06/04/2026
B14: Next Review Date: | C14: 06/04/2027
B15: Document Status: | C15: DRAFT – Confidential
B17: STATUS LEGEND
B18: Compliant | C18: Control is fully implemented and evidenced.
B19: Non-Compliant | C19: Control is missing or failing – remediation required.
B20: Partially | C20: Control is in progress or partially implemented.
B21: N/A | C21: Requirement does not apply to this environment.
B22: Not Tested | C22: Assessment has not yet been performed.

Sheet Summary Dashboard
B2: PCI DSS v4.0 — COMPLIANCE SUMMARY DASHBOARD
B4: Nile Crest Bank (NCB) · Assessment Date: 06/04/2026
B6: # | C6: Requirement | D6: Total Controls | E6: Compliant | F6: Non-Compliant | G6: Partially | H6: N/A
B7: 1 | C7: Install and Maintain Network Security Controls | D7: =COUNTIFS(Checklist!B:B,B7,Checklist!F:F,"<>") -> 5 | E7: =COUNTIFS(Checklist!B:B,B7,Checklist!F:F,"Compliant") -> 5 | F7: =COUNTIFS(Checklist!B:B,B7,Checklist!F:F,"Non-Compliant") -> 0 | G7: =COUNTIFS(Checklist!B:B,B7,Checklist!F:F,"Partially") -> 0 | H7: =COUNTIFS(Checklist!B:B,B7,Checklist!F:F,"N/A") -> 0
B8: 2 | C8: Apply Secure Configurations to All System Components | D8: =COUNTIFS(Checklist!B:B,B8,Checklist!F:F,"<>") -> 4 | E8: =COUNTIFS(Checklist!B:B,B8,Checklist!F:F,"Compliant") -> 4 | F8: =COUNTIFS(Checklist!B:B,B8,Checklist!F:F,"Non-Compliant") -> 0 | G8: =COUNTIFS(Checklist!B:B,B8,Checklist!F:F,"Partially") -> 0 | H8: =COUNTIFS(Checklist!B:B,B8,Checklist!F:F,"N/A") -> 0
B9: 3 | C9: Protect Stored Account Data | D9: =COUNTIFS(Checklist!B:B,B9,Checklist!F:F,"<>") -> 7 | E9: =COUNTIFS(Checklist!B:B,B9,Checklist!F:F,"Compliant") -> 5 | F9: =COUNTIFS(Checklist!B:B,B9,Checklist!F:F,"Non-Compliant") -> 1 | G9: =COUNTIFS(Checklist!B:B,B9,Checklist!F:F,"Partially") -> 1 | H9: =COUNTIFS(Checklist!B:B,B9,Checklist!F:F,"N/A") -> 0
B10: 4 | C10: Protect Cardholder Data with Strong Cryptography During Transmission | D10: =COUNTIFS(Checklist!B:B,B10,Checklist!F:F,"<>") -> 3 | E10: =COUNTIFS(Checklist!B:B,B10,Checklist!F:F,"Compliant") -> 1 | F10: =COUNTIFS(Checklist!B:B,B10,Checklist!F:F,"Non-Compliant") -> 0 | G10: =COUNTIFS(Checklist!B:B,B10,Checklist!F:F,"Partially") -> 1 | H10: =COUNTIFS(Checklist!B:B,B10,Checklist!F:F,"N/A") -> 1
B11: 5 | C11: Protect All Systems and Networks from Malicious Software | D11: =COUNTIFS(Checklist!B:B,B11,Checklist!F:F,"<>") -> 4 | E11: =COUNTIFS(Checklist!B:B,B11,Checklist!F:F,"Compliant") -> 4 | F11: =COUNTIFS(Checklist!B:B,B11,Checklist!F:F,"Non-Compliant") -> 0 | G11: =COUNTIFS(Checklist!B:B,B11,Checklist!F:F,"Partially") -> 0 | H11: =COUNTIFS(Checklist!B:B,B11,Checklist!F:F,"N/A") -> 0
B12: 6 | C12: Develop and Maintain Secure Systems and Software | D12: =COUNTIFS(Checklist!B:B,B12,Checklist!F:F,"<>") -> 5 | E12: =COUNTIFS(Checklist!B:B,B12,Checklist!F:F,"Compliant") -> 5 | F12: =COUNTIFS(Checklist!B:B,B12,Checklist!F:F,"Non-Compliant") -> 0 | G12: =COUNTIFS(Checklist!B:B,B12,Checklist!F:F,"Partially") -> 0 | H12: =COUNTIFS(Checklist!B:B,B12,Checklist!F:F,"N/A") -> 0
B13: 7 | C13: Restrict Access to System Components and Cardholder Data | D13: =COUNTIFS(Checklist!B:B,B13,Checklist!F:F,"<>") -> 3 | E13: =COUNTIFS(Checklist!B:B,B13,Checklist!F:F,"Compliant") -> 3 | F13: =COUNTIFS(Checklist!B:B,B13,Checklist!F:F,"Non-Compliant") -> 0 | G13: =COUNTIFS(Checklist!B:B,B13,Checklist!F:F,"Partially") -> 0 | H13: =COUNTIFS(Checklist!B:B,B13,Checklist!F:F,"N/A") -> 0
B14: 8 | C14: Identify Users and Authenticate Access to System Components | D14: =COUNTIFS(Checklist!B:B,B14,Checklist!F:F,"<>") -> 7 | E14: =COUNTIFS(Checklist!B:B,B14,Checklist!F:F,"Compliant") -> 7 | F14: =COUNTIFS(Checklist!B:B,B14,Checklist!F:F,"Non-Compliant") -> 0 | G14: =COUNTIFS(Checklist!B:B,B14,Checklist!F:F,"Partially") -> 0 | H14: =COUNTIFS(Checklist!B:B,B14,Checklist!F:F,"N/A") -> 0
B15: 9 | C15: Restrict Physical Access to Cardholder Data | D15: =COUNTIFS(Checklist!B:B,B15,Checklist!F:F,"<>") -> 6 | E15: =COUNTIFS(Checklist!B:B,B15,Checklist!F:F,"Compliant") -> 6 | F15: =COUNTIFS(Checklist!B:B,B15,Checklist!F:F,"Non-Compliant") -> 0 | G15: =COUNTIFS(Checklist!B:B,B15,Checklist!F:F,"Partially") -> 0 | H15: =COUNTIFS(Checklist!B:B,B15,Checklist!F:F,"N/A") -> 0
B16: 10 | C16: Log and Monitor All Access to System Components and Cardholder Data | D16: =COUNTIFS(Checklist!B:B,B16,Checklist!F:F,"<>") -> 7 | E16: =COUNTIFS(Checklist!B:B,B16,Checklist!F:F,"Compliant") -> 7 | F16: =COUNTIFS(Checklist!B:B,B16,Checklist!F:F,"Non-Compliant") -> 0 | G16: =COUNTIFS(Checklist!B:B,B16,Checklist!F:F,"Partially") -> 0 | H16: =COUNTIFS(Checklist!B:B,B16,Checklist!F:F,"N/A") -> 0
B17: 11 | C17: Test Security of Systems and Networks Regularly | D17: =COUNTIFS(Checklist!B:B,B17,Checklist!F:F,"<>") -> 6 | E17: =COUNTIFS(Checklist!B:B,B17,Checklist!F:F,"Compliant") -> 6 | F17: =COUNTIFS(Checklist!B:B,B17,Checklist!F:F,"Non-Compliant") -> 0 | G17: =COUNTIFS(Checklist!B:B,B17,Checklist!F:F,"Partially") -> 0 | H17: =COUNTIFS(Checklist!B:B,B17,Checklist!F:F,"N/A") -> 0
B18: 12 | C18: Support Information Security with Organizational Policies and Programs | D18: =COUNTIFS(Checklist!B:B,B18,Checklist!F:F,"<>") -> 10 | E18: =COUNTIFS(Checklist!B:B,B18,Checklist!F:F,"Compliant") -> 9 | F18: =COUNTIFS(Checklist!B:B,B18,Checklist!F:F,"Non-Compliant") -> 0 | G18: =COUNTIFS(Checklist!B:B,B18,Checklist!F:F,"Partially") -> 1 | H18: =COUNTIFS(Checklist!B:B,B18,Checklist!F:F,"N/A") -> 0
B19: TOTAL | D19: =SUM(D7:D18) -> 67 | E19: =SUM(E7:E18) -> 62 | F19: =SUM(F7:F18) -> 1 | G19: =SUM(G7:G18) -> 3 | H19: =SUM(H7:H18) -> 1
B20: OVERALL COMPLIANCE % | D20: =IFERROR(D19/D19*100,0) -> 100

Sheet Checklist
A1: PCI DSS v4.0 — COMPLIANCE CHECKLIST | Nile Crest Bank (NCB)
A2: Assessor: Mohamed Ragab · CISO Samara Almursy Risha · Date: 06/04/2026 · Status: DRAFT
A3: # | B3: Req | C3: Sub-Req | D3: Control Requirement | E3: New Nile Implementation Notes | F3: Status | G3: Evidence / Artefact | H3: Owner | I3: Remediation Deadline
A4: REQUIREMENT 1 — Install and Maintain Network Security Controls
A5: 1 | B5: 1 | C5: 1.1 | D5: Network security controls (NSCs) are defined, owned and managed. | E5: Fortinet FortiGate NSC policy documented and owned by Hossam Badr. | F5: Compliant | H5: Hossam Badr
A6: 2 | B6: 1 | C6: 1.2 | D6: Inbound and outbound traffic is restricted to only what is necessary. | E6: Firewall ruleset reviewed quarterly. Restrictions on all zones are applied | F6: Compliant | H6: Hossam Badr
A7: 3 | B7: 1 | C7: 1.3 | D7: Network access to and from the CDE is restricted. | E7: Base24 Payment Switch isolated in dedicated VLAN. DMZ segments internet-facing services. | F7: Compliant | H7: Hossam Badr
A8: 4 | B8: 1 | C8: 1.4 | D8: Network connections between trusted and untrusted networks are controlled. | E8: Fortinet WAF/reverse proxy between internet zone and core banking zone. | F8: Compliant | H8: Hossam Badr
A9: 5 | B9: 1 | C9: 1.5 | D9: Risks from connecting to untrusted networks are mitigated. | E9: Branch SD-WAN with VLAN segregation. Remote access via MFA-enforced VPN only. | F9: Compliant | H9: Hossam Badr
A10: REQUIREMENT 2 — Apply Secure Configurations to All System Components
A11: 6 | B11: 2 | C11: 2.1 | D11: Processes are in place to manage vendor default accounts and settings. | E11: Hardening baseline applied on Base24, Cisco ISR, Fortinet, and ATM hosts. | F11: Compliant | H11: Mohamed Ragab
A12: 7 | B12: 2 | C12: 2.2 | D12: System components are configured and managed securely. | E12: CIS Benchmarks adopted. Configuration management via change control process. | F12: Compliant | H12: Hossam Badr
A13: 8 | B13: 2 | C13: 2.3 | D13: Wireless environments are configured and managed securely. | E13: Branch Wi-Fi segregated from corporate LAN. WPA3 enforced. Guest SSID isolated. | F13: Compliant | H13: Hossam Badr
A14: 9 | B14: 2 | C14: 2.4 | D14: An inventory of all in-scope system components is maintained. | E14: IT Asset Inventory maintained (see Asset Inventory document). Reviewed quarterly. | F14: Compliant | H14: Sara Ashraf
A15: REQUIREMENT 3 — Protect Stored Account Data
A16: 10 | B16: 3 | C16: 3.1 | D16: Processes to protect stored account data are defined and understood. | E16: Data classification policy defines CHD/SAD handling. DLP policy enforced on Azure. | F16: Compliant | H16: Amira Zaki
A17: 11 | B17: 3 | C17: 3.2 | D17: Storage of sensitive authentication data (SAD) is minimised. | E17: SAD not stored post-authorisation. Base24 configured to truncate PANs in logs. | F17: Partially | H17: Amira Zaki | I17: 46132
A18: 12 | B18: 3 | C18: 3.3 | D18: Sensitive authentication data (SAD) is not retained after authorisation. | E18: Verified with Base24 ACI config audit. No SAD found in test DB extracts. | F18: Non-Compliant | H18: Amira Zaki | I18: 46132
A19: 13 | B19: 3 | C19: 3.4 | D19: Primary account numbers (PANs) are secured with strong cryptography. | E19: PANs encrypted at rest using AES-256 in Oracle RAC. Thales Luna HSM manages keys. | F19: Compliant | H19: Amira Zaki
A20: 14 | B20: 3 | C20: 3.5 | D20: Primary account numbers (PANs) are secured wherever they are displayed. | E20: PAN masking (first 6 / last 4 digits) enforced in all application UI layers. | F20: Compliant | H20: Amira Zaki
A21: 15 | B21: 3 | C21: 3.6 | D21: Cryptographic keys are secured against disclosure and misuse. | E21: Thales Luna HSM used for all key material. Dual-control and split-knowledge enforced. | F21: Compliant | H21: Nour El-Din
A22: 16 | B22: 3 | C22: 3.7 | D22: All cryptographic key management policies and procedures are documented. | E22: Key Management Policy v1.0 approved by CISO. Covers generation, rotation, destruction. | F22: Compliant | H22: Layla Farouk
A23: REQUIREMENT 4 — Protect Cardholder Data with Strong Cryptography During Transmission
A24: 17 | B24: 4 | C24: 4.1 | D24: Processes for protecting cardholder data during transmission are defined. | E24: Data-in-transit policy mandates TLS 1.2+ for all cardholder data channels. | F24: Partially | G24: Updating the TLS 1.2 to 1.3 | H24: Hossam Badr
A25: 18 | B25: 4 | C25: 4.2 | D25: PAN is protected during transmission over untrusted networks. | E25: TLS 1.3 enforced on Online Banking Portal (Azure). ATM PIN encryption via HSM. | F25: Compliant | H25: Hossam Badr
A26: 19 | B26: 4 | C26: 4.3 | D26: PAN is protected during wireless transmission. | E26: No CHD transmitted over wireless. ATM and POS use wired/dedicated encrypted links. | F26: N/A | H26: Hossam Badr
A27: REQUIREMENT 5 — Protect All Systems and Networks from Malicious Software
A28: 20 | B28: 5 | C28: 5.1 | D28: Processes to protect against malicious software are in place. | E28: Anti-malware policy defined. Microsoft Defender deployed on all endpoints. | F28: Compliant | H28: Mohamed Ragab
A29: 21 | B29: 5 | C29: 5.2 | D29: Malicious software (malware) is prevented or detected and addressed. | E29: MS Defender + Sentinel SIEM integration. Real-time alerts to SOC L1/L2. | F29: Compliant | H29: Walid Kamal
A30: 22 | B30: 5 | C30: 5.3 | D30: Anti-malware mechanisms and processes are active and monitored. | E30: Daily AV scan schedules. Sentinel dashboards reviewed by SOC daily. | F30: Compliant | H30: Walid Kamal
A31: 23 | B31: 5 | C31: 5.4 | D31: Anti-phishing mechanisms are in place. | E31: Microsoft Defender for O365 anti-phishing + DLP on Exchange Online. | F31: Compliant | H31: Mohamed Ragab
A32: REQUIREMENT 6 — Develop and Maintain Secure Systems and Software
A33: 24 | B33: 6 | C33: 6.1 | D33: Processes to identify and manage vulnerabilities are implemented. | E33: Vulnerability management process owned by Mohamed Ragab. Monthly scan cycle. | F33: Compliant | H33: Mohamed Ragab
A34: 25 | B34: 6 | C34: 6.2 | D34: Bespoke and custom software is developed securely. | E34: Secure SDLC policy adopted. Mobile app (AWS) follows OWASP MASVS. | F34: Compliant | H34: Nader Saleh
A35: 26 | B35: 6 | C35: 6.3 | D35: Security vulnerabilities are identified and addressed. | E35: 3 critical CVEs open on T24 CBS (60+ days). OPEN FINDING – remediation overdue. | F35: Compliant | H35: Ibrahim Gamal
A36: 27 | B36: 6 | C36: 6.4 | D36: Public-facing web applications are protected against attacks. | E36: Fortinet WAF protects Online Banking Portal and Open Banking API. Rules reviewed monthly. | F36: Compliant | H36: Hossam Badr
A37: 28 | B37: 6 | C37: 6.5 | D37: All web-facing and internet-accessible services are inventoried and protected. | E37: Internet-facing assets: Mobile App (AWS), Online Portal (Azure), Open Banking API. | F37: Compliant | H37: Hossam Badr
A38: REQUIREMENT 7 — Restrict Access to System Components and Cardholder Data
A39: 29 | B39: 7 | C39: 7.1 | D39: Processes to control access to system components are defined. | E39: Access Control Policy in place. Need-to-know enforced for CDE access. | F39: Compliant | H39: Sara Ashraf
A40: 30 | B40: 7 | C40: 7.2 | D40: Access to system components and data is restricted appropriately. | E40: Role-based access on T24, Base24, Oracle RAC. PAM integration via Entra ID. | F40: Compliant | H40: Sara Ashraf
...

Sheet Open Findings
